Workbook

Sheet Acompanhamento Compostagem Alvo
A1: Nome | B1: Data | C1: Origem do resíduo | D1: Destino do resíduo / leira | E1: Peso (kg) | F1: Temperatura (graus) | G1: Temperatura / leira | H1: Observações (números de bombonas) | I1: Tipos de residuos
A2: Karol | B2: 45218 | C2: Carvalheira | D2: 1A | E2: 51.755 | F2: ------------------ | G2: 1A | H2: Início #1A | I2: Carne moida, feijão, cascas de frutas
A3: Karol | B3: 45221 | C3: Carvalheira | D3: 1B | E3: 74.21 | F3: ------------------ | G3: 1B | H3: Início #1B | I3: Cascas de frutas, Arroz, Feijão e Macarrão
A4: Karol | B4: 45224 | C4: Carvalheira | D4: 1C | E4: 88.53 | F4: ------------------ | G4: 1C | H4: Início #1C | I4: Cascas de frutas, Macarrão, salsicha, feijão
A5: Karol | B5: 45226 | C5: Carvalheira | D5: 1A | E5: 25.46 | F5: 40° | G5: 1A | H5: Apenas 1 bombona, devido a Cavarlheira ter descido os residuos apos as 16hrs! Veio plásticos | I5: Cascas de frutas e Feijão
A6: Karol | B6: 45228 | C6: Carvalheira | D6: 1A | E6: 72.28 | F6: 41° | G6: 1A | H6: Alimentado na 1A novamente, devido a ser o restante das bombonas de ontem | I6: Cascas de frutas e Macarrão
A7: Karol | B7: 45233 | C7: Carvalheira | D7: 1B | E7: 102.65 | F7: 49° | G7: 1B | H7: As tampas internas não estão sendo bem utilizadas | I7: Cascas de frutas, arroz, Feijão e resto de galinha
A8: Karol | B8: 45236 | C8: Carvalheira | D8: 1C | E8: 108.15 | F8: 51° | G8: 1C | H8: Sem presença de sacolas plasticas | I8: Cascas de frutas, arroz, Feijão e resto de galinha
A9: Karol | B9: 45240 | C9: Carvalheira | D9: 1A | E9: 51.09 | F9: 50° | G9: 1A | H9: Sem presença de sacolas plasticas e odor forte | I9: Resto de comida e ossos
A10: Karol | B10: 45247 | C10: Carvalheira | D10: 1B | E10: 170.6 | F10: 43° | G10: 1B | H10: Presença de mofo e os microorganismos | I10: Cascas de frutas, Arroz, Feijoada e Carne
A11: INÍCIO DA DIVISÃO DA LEIRA EM 4 PARTES (1A; 1B; 1C; 1D)
A12: Abul | B12: 45251 | C12: Carvalheira | D12: 1C | E12: 132.4 | F12: 47° | G12: 1C | H12: Presença de mofo e os microorganismos | I12: Cascas de frutas, arroz, Feijão e resto de galinha
A13: Karol | B13: 45258 | C13: Carvalheira | D13: 1A | E13: 136.52 | F13: 50° | G13: 1A | I13: Cascas de Laranja, Arroz e Feijão
A14: Karol | B14: 45265 | C14: Carvalheira | D14: 1B | E14: 208.2 | F14: 40° | G14: 1B | H14: Presença de plastico nas bombonas. Temperatura seções: 1A - 60° | 1B:40° | 1C- 52° | 1D: 56° | I14: Cascas de Laranja, Arroz e Macarrão
A15: Karol | B15: 45269 | C15: Carvalheira | D15: 1C | E15: 158.79 | F15: 49° | G15: 1C | H15: Bastante casca de laranja (7 bombonas) | I15: Cascas de Laranja e Arroz
A16: Rani | B16: 45272 | C16: Carvalheira | D16: 1D | E16: 163.04 | F16: 49° | G16: 1D | H16: Bastante casca de laranja (4 bombonas) | I16: Cascas de Laranja, Arroz e Feijão
A17: Mayra | B17: 45275 | C17: Carvalheira | D17: 1A | E17: 212.85 | F17: 40° | G17: 1A | H17: Bastante resto de comida (7 bombonas) | I17: Cascas de Laranja, abacaxi, Arroz, macarrão, embutidos e Feijão
A18: Karol | B18: 45279 | C18: Carvalheira | D18: 1B | E18: 136.87 | F18: 52° | G18: 1B | H18: Bastante resto de comida (4 bombonas) | I18: Cascas de Laranja, abacaxi, Arroz, macarrão, embutidos e Feijão
A19: Karol | B19: 45282 | C19: Carvalheira | D19: 1C | E19: 206.75 | F19: 54° | G19: 1C | H19: Bastante casca de frutas (6 bombonas) | I19: Cascas de Laranja, abacaxi, limão, Arroz, macarrão, ossos e Feijão
A20: Karol | B20: 45286 | C20: Carvalheira | D20: 1D | E20: 188.67 | F20: 60° | G20: 1D | H20: Bastante casca de frutas (6 bombonas) | I20: Cascas de Laranja, abacaxi, limão, Arroz, macarrão e ossos
A21: Karol | B21: 45290 | C21: Carvalheira | D21: 1A | E21: 121.56 | F21: 50° | G21: 1A | H21: Bastante casca de frutas (6 bombonas) | I21: Cascas de Laranja, abacaxi, limão, maracuja e Arroz
A22: Mayra | B22: 45294 | C22: Carvalheira | D22: 1B | E22: 200.2 | F22: 58° | G22: 1B | H22: Bastante casca de frutas (9 bombonas) | I22: Cascas de Laranja, abacaxi, limão, maracuja e Arroz
A23: Karol | B23: 45297 | C23: Carvalheira | D23: 1C | E23: 75.2 | F23: 54° | G23: 1C | H23: Bastante casca de frutas (5 bombonas) | I23: Casca de laranja, limão, abacaxi (inclusive inteiro) e acerola
A24: Karol | B24: 45300 | C24: Carvalheira | D24: 1D | E24: 120 | F24: 60° | G24: 1D | H24: Bastante casca de frutas (4 bombonas) | I24: Casca de laranja, limão e acerola
A25: Karol | B25: 45303 | C25: Carvalheira | D25: 2A | E25: 81.8 | F25: Inicio | G25: 2A | H25: Bastante casca de frutas (4 bombonas) | I25: Casca de laranja, limão e acerola
... A36: Rani | B36: 45341 | C36: Carrefour/Bompreço | D36: 2B | E36: 175.61 | F36: 58° | G36: 2B | H36: 7 bombonas, bem misturadas | I36: Massa de pão, Batata, Pepino, Pimentão, Coxinha Pao integral, Cuscuz, Salgadinho, Arroz, Carne, Queijo, Laranja, mamão, melancia, berinjela, beterraba e massa de pão
A37: Karol | B37: 45344 | C37: Carrefour/Bompreço | D37: 2C | E37: 171.41 | G37: 2C | H37: 7 bombonas, bem misturadas | I37: Uva, batata, maça, galinha, pão, carne, cuscus, farinha,alface, rucula, berinjela, queijos
A38: Karol | B38: 45344 | C38: Carvalheira | D38: 2D | E38: 47.1 | G38: 2D | H38: 4 bombonas, sendo 2 de cascas e 2 de resto de comida | I38: Arroz, Macarrão, Galinha, Feijão, Casca de Laranja e Limão
A39: Rani | B39: 45345 | C39: Carvalheira | D39: 2A | E39: 46.89 | F39: 62° | G39: 2A | H39: 5 bombonas, 3 de cascas e 2 de resto de comida | I39: Casca de laranja, arroz, feijão, galinha e macarrao
A40: Rani | B40: 45345 | C40: Carrefour/Bompreço | D40: 2B | E40: 195 | F40: 62° | G40: 2B | H40: 7 do bombreço bem misturadas | I40: maioria contendo pão, frutas, verduras, carne, galinha, queijo, cuscus e farinha
A41: Mayra | B41: 45348 | C41: Carrefour/Bompreço | D41: 2A | E41: 326.76 | F41: 60° | G41: 2A | H41: 15 bombonas Carrefour/Bompreço
A42: Mayra | B42: 45348 | C42: Carvalheira | D42: 2A | E42: 102.45 | F42: 60° | G42: 2A | H42: 7 da carvalheira (5 de cascas de laranja e 2 de comida)
A43: Karol | B43: 45350 | C43: Carrefour/Bompreço | D43: 2D | E43: 205.75 | F43: 60° | G43: 2D | H43: 10 Bombonas bem misturadas | I43: Queijo, pães, ração de gato, maça, laranja, uva, melancia, maracuja, melão, farinha, cuscuz, carne, galinha, linguiça, presunto, fiambre
A44: Karol | B44: 45350 | C44: Carvalheira | D44: 2C | E44: 58.55 | F44: 59° | G44: 2C | H44: 5 bombonas, 3 de cascas; Laranja, limão e abacate e 2 de resto de comida | I44: Laranja, Limão, Abacate, arroz, feijão, macarrão, galinha e ossos de carne
A45: Mayra | B45: 45352 | C45: Carvalheira | D45: 3A | E45: 62.3 | F45: Inicio | G45: 3A | H45: 3 bombonas (casca de laranja) | I45: Casca de laranja
A46: Mayra | B46: 45352 | C46: Carrefour/Bompreço | D46: 3A | E46: 110.9 | F46: Inicio | G46: 3A | H46: 6 bombonas (pão, frios, frutas, verduras) | I46: pão, frios, frutas, verduras
A47: Karol | B47: 45355 | C47: Carrefour/Bompreço | D47: 3B | E47: 110.75 | F47: Inicio | G47: 3B | H47: 6 bombonas Carrefour/Bompreço: (ração, pães, frutas e verduras) | I47: ração, pães, frutas e verduras
A48: Karol | B48: 45355 | C48: Carvalheira | D48: 3B | E48: 96.5 | F48: Inicio | G48: 3B | H48: 7 bombonas da Carvalheira: (5 bombonas com casca de Laranja e 3 de resto de comida: Arroz, Feijão, macarrao, carne, galinha, Cuscuz) | I48: 5 bombonas com casca de Laranja e 3 de resto de comida: Arroz, Feijão, macarrao, carne, galinha, Cuscuz
A49: Karol | B49: 45355 | C49: Doca C | D49: 3B | E49: 67.25 | F49: Inicio | G49: 3B | H49: 4 bombonas doca C: (3 de cascas de laranja e 1 de resto de comida) | I49: 3 de cascas de laranja e 1 de resto de comida
A50: Rani | B50: 45356 | C50: Carrefour/Bompreço | D50: 2A | E50: 109.45 | F50: 59° | G50: 2A
...

Sheet Página17

Sheet Peso x tempo
B1: Data | C1: Peso por alimentação | D1: Peso acumulado | E1: Matéria SECA (carros de mão)
B2: 45218 | C2: 51.75 | D2: 51.75
B3: 45221 | C3: 74.21 | D3: =D2+C3 -> 125.96
B4: 45224 | C4: 88.53 | D4: =D3+C4 -> 214.49
B5: 45226 | C5: 25.46 | D5: =D4+C5 -> 239.95
B6: 45228 | C6: 72.28 | D6: =D5+C6 -> 312.23
B7: 45233 | C7: 102.65 | D7: =D6+C7 -> 414.88
B8: 45236 | C8: 108.15 | D8: =D7+C8 -> 523.03
B9: 45240 | C9: 51.09 | D9: =D8+C9 -> 574.12
B10: 45247 | C10: 170.6 | D10: =D9+C10 -> 744.72
B11: 45251 | C11: 132.4 | D11: =D10+C11 -> 877.12
B12: 45258 | C12: 136.52 | D12: =D11+C12 -> 1013.64
B13: 45265 | C13: 208.2 | D13: =D12+C13 -> 1221.84
B14: 45269 | C14: 158.79 | D14: =D13+C14 -> 1380.63
... B33: 45337 | C33: 103.76 | D33: =D32+C33 -> 3777.83
B34: 45341 | C34: =175.61+'Acompanhamento Compostagem Alvo'!E35 -> 279.36 | D34: =D33+C34 -> 4057.19
B35: 45345 | C35: ='Acompanhamento Compostagem Alvo'!E39+'Acompanhamento Compostagem Alvo'!E40 -> 241.89 | D35: =D34+C35 -> 4299.08
B36: 45348 | C36: ='Acompanhamento Compostagem Alvo'!E41+'Acompanhamento Compostagem Alvo'!E42 -> 429.21 | D36: =D35+C36 -> 4728.29
B37: 45350 | C37: ='Acompanhamento Compostagem Alvo'!E44+'Acompanhamento Compostagem Alvo'!E43 -> 264.3 | D37: =D36+C37 -> 4992.59
B38: 45352 | C38: 287.94 | D38: =D37+C38 -> 5280.53
B39: 45355 | C39: 274.5 | D39: =D38+C39 -> 5555.03
B40: 45356 | C40: 156.15 | D40: =D39+C40 -> 5711.18
B41: 45358 | C41: 305.65 | D41: =D40+C41 -> 6016.83
B42: 45359 | C42: 293.67 | D42: =D41+C42 -> 6310.5
B43: 45362 | C43: 266.23 | D43: =D42+C43 -> 6576.73
B44: 45364 | C44: 345.95 | D44: =D43+C44 -> 6922.68
B45: 45366 | C45: ='Acompanhamento Compostagem Alvo'!E64+'Acompanhamento Compostagem Alvo'!E65+'Acompanhamento Compostagem Alvo'!E66 -> 449.75 | D45: =D44+C45 -> 7372.43
B46: 45370 | C46: 323.98 | D46: =D45+C46 -> 7696.41
B47: 45372 | C47: 335.49 | D47: =D46+C47 -> 8031.9
B48: 45373 | C48: ='Acompanhamento Compostagem Alvo'!E73+'Acompanhamento Compostagem Alvo'!E74 -> 121.34 | D48: =D47+C48 -> 8153.24
B49: 45376 | C49: ='Acompanhamento Compostagem Alvo'!E76+'Acompanhamento Compostagem Alvo'!E75 -> 397.83 | D49: =D48+C49 -> 8551.07
B50: 45379 | C50: ='Acompanhamento Compostagem Alvo'!E79+'Acompanhamento Compostagem Alvo'!E78+'Acompanhamento Compostagem Alvo'!E77 -> 481.47 | D50: =D49+C50 -> 9032.54
B51: 45383 | C51: 602.55 | D51: =D50+C51 -> 9635.09
B52: 45385 | C52: 557.4 | D52: =D51+C52 -> 10192.49
B53: 45387 | C53: ='Acompanhamento Compostagem Alvo'!E87+'Acompanhamento Compostagem Alvo'!E88+'Acompanhamento Compostagem Alvo'!E89+'Acompanhamento Compostagem Alvo'!E90 -> 527.39 | D53: =D52+C53 -> 10719.88
B54: 45390 | C54: 451.92 | D54: =D53+C54 -> 11171.8
B55: 45392 | C55: 345.6 | D55: =D54+C55 -> 11517.4
B56: 45394 | C56: 433.74 | D56: =D55+C56 -> 11951.14
B57: 45397 | C57: 496 | D57: =D56+C57 -> 12447.14
B58: 45399 | C58: 475.23 | D58: =D57+C58 -> 12922.37
...

Sheet fonte x peso x tempo
B1: Carvalheira | C1: Carrefour (Bompreço) | D1: Doca C | E1: Adm | F1: Tio Armênio | G1: Plim | H1: Gabriel Bacelar | I1: Terra | J1: Brulee | K1: Companhia do Choop | L1: Zio | M1: Yoshi | N1: Toscana
A2: 45218 | B2: 51.755
A3: 45221 | B3: 74.21
A4: 45224 | B4: 88.53
A5: 45226 | B5: 25.46
A6: 45228 | B6: 72.28
A7: 45233 | B7: 102.65
A8: 45236 | B8: 108.149
A9: 45240 | B9: 51.09
A10: 45247 | B10: 170.6
A11: 45251 | B11: 132.4
A12: 45258 | B12: 136.52
A13: 45265 | B13: 208.2
... A33: 45337 | B33: 103.76
A34: 45341 | B34: 103.75 | C34: 175.61
A35: 45344 | B35: 47.1 | C35: 171.41
A36: 45345 | B36: 46.89 | C36: 195
A37: 45348 | B37: 102.45 | C37: 326.76
A38: 45350 | B38: 58.55 | C38: 205.75
A39: 45352 | B39: 62.3 | C39: 110.9
A40: 45355 | B40: 96.5 | C40: 110.75 | D40: 67.25
A41: 45356 | B41: 0 | C41: 109.45 | D41: 46.7
A42: 45358 | B42: 66 | C42: 166.5 | D42: 63.8 | E42: 9.35
A43: 45359 | B43: 21.32 | C43: 233.45 | D43: 38.9 | E43: 0
A44: 45362 | B44: 101.88 | C44: 164.35 | D44: 0 | E44: 0
A45: 45364 | B45: 45.75 | C45: 281 | D45: 19.15 | E45: 0
A46: 45366 | B46: 62.3 | C46: 313.9 | D46: 73.55 | E46: 0
A47: 45370 | B47: 61.5 | C47: 262.48 | D47: 0 | E47: 0
A48: 45372 | B48: 39 | C48: 218.2 | D48: 66.79 | E48: 11.5
A49: 45373 | B49: 31.88 | C49: 89.46 | D49: 0 | E49: 0
A50: 45376 | B50: 74.98 | C50: 322.85 | D50: 0 | E50: 0
A51: 45379 | B51: 102.61 | C51: 368.96 | D51: 0 | E51: 9.9
A52: 45383 | B52: 77.3 | C52: 402.88 | D52: 0 | E52: 0 | F52: 122.36
A53: 45385 | B53: 85.3 | C53: 233.78 | D53: 103.77 | E53: 0 | F53: 134.55
A54: 45387 | B54: 41.16 | C54: 225.56 | D54: 54.72 | E54: 0 | F54: 205.95
A55: 45390 | B55: 47.8 | C55: 145.23 | D55: 20.1 | E55: 0 | F55: 238.79
A56: 45392 | B56: 16.8 | C56: 210 | D56: 27.89 | E56: 0 | F56: 91
A57: 45394 | B57: 52.3 | C57: 180.06 | D57: 10.26 | E57: 0 | F57: 191.1
A58: 45397 | B58: 0 | C58: 244.9 | D58: 50.45 | E58: 0 | F58: 200.65
A59: 45399 | B59: 0 | C59: 193.86 | D59: 56.11 | E59: 0 | F59: 225.25
...

Sheet Fonte - Peso - Lojas
A1: DATA | B1: TERRA | C1: ZIO | D1: YOSHI | E1: BRULEE | F1: CIA DO CHOPP | G1: GABRIEL BACELAR
A2: Pesagem anterior | B2: 0 | C2: 0 | D2: 0 | E2: 0 | F2: 0 | G2: 1249.12
A3: 46037 | B3: 46.45 | C3: Não tinha iniciado | D3: 0 | E3: 0 | F3: 0 | G3: 0
A4: 46038 | B4: 0 | C4: Não tinha iniciado | D4: 0 | E4: 0 | F4: 0 | G4: 0
A5: 46041 | B5: 204.6 | C5: Não tinha iniciado | D5: 97 | E5: 0 | F5: 120.3 | G5: 0
A6: 46043 | B6: 78 | C6: Não tinha iniciado | D6: 68.36 | E6: 0 | F6: 0 | G6: 0
A7: 46044 | B7: 0 | C7: Não tinha iniciado | D7: 58.8 | E7: 0 | F7: 0 | G7: 0
A8: 46045 | B8: 86.32 | C8: Não tinha iniciado | D8: 0 | E8: 0 | F8: 0 | G8: 0
A9: 46048 | B9: 132.5 | C9: Não tinha iniciado | D9: 68.45 | E9: 12.7 | F9: 61.69 | G9: 0
A10: 46049 | B10: 72.19 | C10: Não tinha iniciado | D10: 46.1 | E10: 0 | F10: 38.55 | G10: 89.35
A11: 46050 | B11: 45.44 | C11: 0 | D11: 81.41 | E11: 0 | F11: 37.23 | G11: 0
A12: 46051 | B12: 46.5 | C12: 0 | D12: 23.12 | E12: 0 | F12: 26.8 | G12: 0
A13: 46052 | B13: 168.52 | C13: 0 | D13: 28.36 | E13: 35.7 | F13: 29.1 | G13: 0
A14: 46055 | B14: 256.2 | C14: 0 | D14: 79.2 | E14: 0 | F14: 72.5 | G14: 0
A15: 46056 | B15: 78.15 | C15: 0 | D15: 28.98 | E15: 0 | F15: 0 | G15: 0
A16: 46057 | B16: 32.58 | C16: 0 | D16: 14.68 | E16: 0 | F16: 0 | G16: 30.88
A17: 46058 | B17: 48.55 | C17: 23 | D17: 15.75 | E17: 0 | F17: 19 | G17: 0
A18: 46059 | B18: 37.1 | C18: 0 | D18: 28.25 | E18: 25.89 | F18: 27.95 | G18: 21.95
A19: 46062 | B19: 204.23 | C19: 60.29 | D19: 56.6 | E19: 0 | F19: 104.3 | G19: 40.1
A20: 46063 | B20: 86.3 | C20: 34.88 | D20: 0 | E20: 0 | F20: 0 | G20: 0
A21: 46065 | B21: 149.73 | C21: 0 | D21: 108.77 | E21: 0 | G21: 0
A22: 46066 | B22: 79.06 | C22: 46.28 | D22: 18.86 | E22: 0 | F22: 30.15 | G22: 0
A23: 46069 | B23: 96.3 | C23: 101 | D23: 105.3 | E23: 0 | F23: 78.15 | G23: 0
A24: 46071 | B24: 68.45 | C24: 0 | D24: 30.02 | E24: 0 | F24: 32.4 | G24: 78.15
A25: 46072 | B25: 86.2 | C25: 0 | D25: 104.55 | E25: 0 | F25: 80.01 | G25: 37.2
A26: 46073 | B26: 189.22 | C26: 91.15 | D26: 71.15 | E26: 55.63 | F26: 0 | G26: 0
A27: 46076 | B27: 140.54 | C27: 89.2 | D27: 150.21 | E27: 0 | F27: 0 | G27: 78.25
A28: 46077 | B28: 48.98 | C28: 84.5 | D28: 0 | E28: 0 | F28: 0 | G28: 0
A29: 46078 | B29: 28.1 | C29: 40.15 | D29: 24.4 | E29: 0 | F29: 26.3 | G29: 0
A30: 46079 | B30: 61.32 | C30: 58.73 | D30: 0 | E30: 0 | F30: 38.9 | G30: 0
A31: 46080 | B31: 38.85 | C31: 43.4 | D31: 33.95 | E31: 0 | F31: 27.2 | G31: 0
A32: 46083 | B32: 165.08 | C32: 162.19 | D32: 96.02 | E32: 36.05 | F32: 24.15 | G32: 0
A33: 46084 | B33: 68.45 | C33: 19.1 | D33: 29.83 | E33: 0 | F33: 0 | G33: 0
... A42: 46098 | B42: 37.59 | C42: 58.15 | D42: 21.71 | E42: 0 | F42: 34.35 | G42: 0
A43: 46099 | B43: 41.23 | C43: 60.8 | D43: 18.98 | E43: 20 | F43: 30.15
A44: 46100 | B44: 26.85 | C44: 0 | D44: 26.15 | E44: 0 | F44: 55.2 | G44: 0
A45: 46101 | B45: 0 | C45: 21.08 | D45: 15.17 | E45: 0 | F45: 0 | G45: 0
A46: 46104 | B46: 145.49 | C46: 56.02 | D46: 107.89 | E46: 24.2 | F46: 103.98 | G46: 0
A47: 46105 | B47: 0 | C47: 90.28 | D47: 50.17 | E47: 0 | F47: 0 | G47: 0
A48: 46106 | B48: 101 | C48: 0 | D48: 102.33 | E48: 0 | F48: 0 | G48: 103.2
...

Sheet Peso x Caixa
A2: N° caixa | B2: Peso ja compostado | C2: Status Atual | D2: Peso em que entrou em descanso | E2: Data da ultima alimentação
A3: Caixa 1 | B3: 2602.82 | C3: Em descanso | D3: =SUM('Acompanhamento Compostagem Alvo'!E765+'Acompanhamento Compostagem Alvo'!E767+'Acompanhamento Compostagem Alvo'!E770+'Acompanhamento Compostagem Alvo'!E779+'Acompanhamento Compostagem Alvo'!E784+'Acompanhamento Compostagem Alvo'!E791+'Acompanhamento Compostagem Alvo'!E792+'Acompanhamento Compostagem Alvo'!E801+'Acompanhamento Compostagem Alvo'!E807+'Acompanhamento Compostagem Alvo'!E833) -> 681.69 | E3: 46108
A4: Caixa 2 | B4: 2481.65 | C4: Em descanso | D4: =SUM('Acompanhamento Compostagem Alvo'!E761+'Acompanhamento Compostagem Alvo'!E768+'Acompanhamento Compostagem Alvo'!E771+'Acompanhamento Compostagem Alvo'!E785+'Acompanhamento Compostagem Alvo'!E802+'Acompanhamento Compostagem Alvo'!E834+'Acompanhamento Compostagem Alvo'!E840) -> 653.96 | E4: 46108
A5: Caixa 3 | B5: 2431.47 | C5: Em descanso | D5: =SUM('Acompanhamento Compostagem Alvo'!E764+'Acompanhamento Compostagem Alvo'!E769+'Acompanhamento Compostagem Alvo'!E777+'Acompanhamento Compostagem Alvo'!E780+'Acompanhamento Compostagem Alvo'!E787+'Acompanhamento Compostagem Alvo'!E836+'Acompanhamento Compostagem Alvo'!E839) -> 486.13 | E5: 46098
A6: Caixa 4 | B6: 2300.64 | C6: Em descanso | D6: =SUM('Acompanhamento Compostagem Alvo'!E708+'Acompanhamento Compostagem Alvo'!E709+'Acompanhamento Compostagem Alvo'!E710+'Acompanhamento Compostagem Alvo'!E735+'Acompanhamento Compostagem Alvo'!E737+'Acompanhamento Compostagem Alvo'!E750+'Acompanhamento Compostagem Alvo'!E786+'Acompanhamento Compostagem Alvo'!E793+'Acompanhamento Compostagem Alvo'!E798+'Acompanhamento Compostagem Alvo'!E845+'Acompanhamento Compostagem Alvo'!E860) -> 692.72 | E6: 46105
A7: Caixa 5 | B7: 2226.74 | C7: Em descanso | D7: ='Acompanhamento Compostagem Alvo'!E729+'Acompanhamento Compostagem Alvo'!E730+'Acompanhamento Compostagem Alvo'!E736+'Acompanhamento Compostagem Alvo'!E738+'Acompanhamento Compostagem Alvo'!E745+'Acompanhamento Compostagem Alvo'!E812+'Acompanhamento Compostagem Alvo'!E816+'Acompanhamento Compostagem Alvo'!E829+'Acompanhamento Compostagem Alvo'!E837+'Acompanhamento Compostagem Alvo'!E847 -> 717.33 | E7: 46136 | F7: Colocar nova coluna para a nova alimentação - pois a caixa ja foi esvaziada, alimentada e vai ser utilizada novamente
A8: Caixa 6 | B8: 2066.93 | C8: Em descanso | D8: ='Acompanhamento Compostagem Alvo'!E846+'Acompanhamento Compostagem Alvo'!E848+'Acompanhamento Compostagem Alvo'!E852+'Acompanhamento Compostagem Alvo'!E859+'Acompanhamento Compostagem Alvo'!E865+'Acompanhamento Compostagem Alvo'!E868+'Acompanhamento Compostagem Alvo'!E870+'Acompanhamento Compostagem Alvo'!E886+'Acompanhamento Compostagem Alvo'!E887+'Acompanhamento Compostagem Alvo'!E895 -> 758.82 | E8: 46162
A9: Caixa 7 | B9: 1640.73 | C9: Em descanso | D9: =SUM('Acompanhamento Compostagem Alvo'!E849+'Acompanhamento Compostagem Alvo'!E869+'Acompanhamento Compostagem Alvo'!E871+'Acompanhamento Compostagem Alvo'!E892+'Acompanhamento Compostagem Alvo'!E906+'Acompanhamento Compostagem Alvo'!E913+'Acompanhamento Compostagem Alvo'!E909) -> 605.91 | E9: 46230
A10: Caixa 8 | B10: 2213.53 | C10: Em descanso | D10: ='Acompanhamento Compostagem Alvo'!E815+'Acompanhamento Compostagem Alvo'!E824+'Acompanhamento Compostagem Alvo'!E830+'Acompanhamento Compostagem Alvo'!E832+'Acompanhamento Compostagem Alvo'!E838+'Acompanhamento Compostagem Alvo'!E853 -> 549.57 | E10: 46139
A11: Caixa 9 | B11: 1981.13 | C11: Em descanso | D11: =SUM('Acompanhamento Compostagem Alvo'!E844+'Acompanhamento Compostagem Alvo'!E863+'Acompanhamento Compostagem Alvo'!E876+'Acompanhamento Compostagem Alvo'!E891+'Acompanhamento Compostagem Alvo'!E898+'Acompanhamento Compostagem Alvo'!E902+'Acompanhamento Compostagem Alvo'!E914) -> 731.97 | E11: 46171
A12: Caixa 10 | B12: 1594.26 | C12: Em descanso | D12: =SUM('Acompanhamento Compostagem Alvo'!E857+'Acompanhamento Compostagem Alvo'!E862+'Acompanhamento Compostagem Alvo'!E864+'Acompanhamento Compostagem Alvo'!E877+'Acompanhamento Compostagem Alvo'!E889+'Acompanhamento Compostagem Alvo'!E899+'Acompanhamento Compostagem Alvo'!E900+'Acompanhamento Compostagem Alvo'!E903+'Acompanhamento Compostagem Alvo'!E915) -> 696.15 | E12: 46203
A13: Caixa 11 | B13: 2054.25 | C13: Em descanso | D13: =SUM('Acompanhamento Compostagem Alvo'!E695+'Acompanhamento Compostagem Alvo'!E704+'Acompanhamento Compostagem Alvo'!E705+'Acompanhamento Compostagem Alvo'!E706+'Acompanhamento Compostagem Alvo'!E707+'Acompanhamento Compostagem Alvo'!E740+'Acompanhamento Compostagem Alvo'!E741+'Acompanhamento Compostagem Alvo'!E748+'Acompanhamento Compostagem Alvo'!E755+'Acompanhamento Compostagem Alvo'!E756+'Acompanhamento Compostagem Alvo'!E772+'Acompanhamento Compostagem Alvo'!E789+'Acompanhamento Compostagem Alvo'!E794+'Acompanhamento Compostagem Alvo'!E799) -> 743.99 | E13: 46171
A14: Caixa 12 | B14: 2384.89 | C14: Em descanso | D14: =SUM('Acompanhamento Compostagem Alvo'!E854+'Acompanhamento Compostagem Alvo'!E858+'Acompanhamento Compostagem Alvo'!E866+'Acompanhamento Compostagem Alvo'!E879+'Acompanhamento Compostagem Alvo'!E890+'Acompanhamento Compostagem Alvo'!E901+'Acompanhamento Compostagem Alvo'!E911) -> 611.02 | E14: 46203
A15: Caixa 13 | B15: 2588.74 | C15: Em descanso | D15: =SUM('Acompanhamento Compostagem Alvo'!E850+'Acompanhamento Compostagem Alvo'!E867+'Acompanhamento Compostagem Alvo'!E894+'Acompanhamento Compostagem Alvo'!E897+'Acompanhamento Compostagem Alvo'!E912+'Acompanhamento Compostagem Alvo'!E907+'Acompanhamento Compostagem Alvo'!E908) -> 669.23 | E15: 46203
A16: Caixa 14 | B16: 2245.89 | C16: Esvaziamento | D16: ='Acompanhamento Compostagem Alvo'!E753+'Acompanhamento Compostagem Alvo'!E762+'Acompanhamento Compostagem Alvo'!E776+'Acompanhamento Compostagem Alvo'!E783+'Acompanhamento Compostagem Alvo'!E790 -> 489.7 | E16: 46188
A17: Caixa 15 | B17: 2878.27 | C17: Em descanso | D17: =SUM('Acompanhamento Compostagem Alvo'!E796+'Acompanhamento Compostagem Alvo'!E808+'Acompanhamento Compostagem Alvo'!E817+'Acompanhamento Compostagem Alvo'!E822+'Acompanhamento Compostagem Alvo'!E823+'Acompanhamento Compostagem Alvo'!E841+'Acompanhamento Compostagem Alvo'!E851+'Acompanhamento Compostagem Alvo'!E855) -> 771.23 | E17: 46140
A18: Caixa 16 | B18: 3117.95 | C18: Em descanso | D18: =SUM('Acompanhamento Compostagem Alvo'!E805+'Acompanhamento Compostagem Alvo'!E809+'Acompanhamento Compostagem Alvo'!E818+'Acompanhamento Compostagem Alvo'!E825+'Acompanhamento Compostagem Alvo'!E835+'Acompanhamento Compostagem Alvo'!E842+'Acompanhamento Compostagem Alvo'!E856) -> 615.17 | E18: 46140
A19: Caixa 17 | B19: 1370.44 | C19: Em descanso | D19: =SUM('Acompanhamento Compostagem Alvo'!E758+'Acompanhamento Compostagem Alvo'!E810+'Acompanhamento Compostagem Alvo'!E819+'Acompanhamento Compostagem Alvo'!E826+'Acompanhamento Compostagem Alvo'!E831+'Acompanhamento Compostagem Alvo'!E843) -> 553.44 | E19: 46134
A20: Caixa 18 | B20: 1948.49 | C20: Em descanso | D20: =SUM('Acompanhamento Compostagem Alvo'!E828+'Acompanhamento Compostagem Alvo'!E827+'Acompanhamento Compostagem Alvo'!E821+'Acompanhamento Compostagem Alvo'!E806+'Acompanhamento Compostagem Alvo'!E781+'Acompanhamento Compostagem Alvo'!E861) -> 563.14 | E20: 46142
A21: Caixa 19 | C21: Não ativada
A22: Caixa 20 | C22: Não ativada
A23: Caixa 21 | C23: Não ativada
A24: Caixa 22 | C24: Não ativada
A25: Caixa 23 | B25: ='Acompanhamento Compostagem Alvo'!E1012+'Acompanhamento Compostagem Alvo'!E1018+'Acompanhamento Compostagem Alvo'!E1024+'Acompanhamento Compostagem Alvo'!E1025 -> 414
A26: Caixa 24 | B26: =SUM('Acompanhamento Compostagem Alvo'!E1009+'Acompanhamento Compostagem Alvo'!E1013+'Acompanhamento Compostagem Alvo'!E1019+'Acompanhamento Compostagem Alvo'!E1022+'Acompanhamento Compostagem Alvo'!E1028) -> 475
A27: Caixa 25 | B27: =SUM('Acompanhamento Compostagem Alvo'!E970+'Acompanhamento Compostagem Alvo'!E977++'Acompanhamento Compostagem Alvo'!E984+'Acompanhamento Compostagem Alvo'!E990+'Acompanhamento Compostagem Alvo'!E993+'Acompanhamento Compostagem Alvo'!E997) -> 704.4 | C27: em descanso | E27: 46227
A28: Caixa 26 | B28: =SUM('Acompanhamento Compostagem Alvo'!E975+'Acompanhamento Compostagem Alvo'!E978+'Acompanhamento Compostagem Alvo'!E982+'Acompanhamento Compostagem Alvo'!E989+'Acompanhamento Compostagem Alvo'!E996+'Acompanhamento Compostagem Alvo'!E1010) -> 676.85 | C28: em descanso

Sheet peso x leira
A1: Leira | B1: peso atual | C1: 1° descanso | D1: 1a mobilização | E1: 2° descanso | F1: 2a mobilização | G1: 3° descanso
A2: 1 | B2: =SUM('Acompanhamento Compostagem Alvo'!E2+'Acompanhamento Compostagem Alvo'!E3+'Acompanhamento Compostagem Alvo'!E4+'Acompanhamento Compostagem Alvo'!E5+'Acompanhamento Compostagem Alvo'!E6+'Acompanhamento Compostagem Alvo'!E7+'Acompanhamento Compostagem Alvo'!E8+'Acompanhamento Compostagem Alvo'!E9+'Acompanhamento Compostagem Alvo'!E10+'Acompanhamento Compostagem Alvo'!E10+'Acompanhamento Compostagem Alvo'!E12+'Acompanhamento Compostagem Alvo'!E13+'Acompanhamento Compostagem Alvo'!E14+'Acompanhamento Compostagem Alvo'!E15+'Acompanhamento Compostagem Alvo'!E16+'Acompanhamento Compostagem Alvo'!E17+'Acompanhamento Compostagem Alvo'!E18+'Acompanhamento Compostagem Alvo'!E19+'Acompanhamento Compostagem Alvo'!E20+'Acompanhamento Compostagem Alvo'!E21+'Acompanhamento Compostagem Alvo'!E22+'Acompanhamento Compostagem Alvo'!E23+'Acompanhamento Compostagem Alvo'!E24 +B7) -> 11119.795 | C2: até 09/01/2024 = 2.805,78kg | D2: esvaziada dia 09/04/2024 com 2ton aprox. | E2: De 8/5 a 30/7 = 8.143,42Kg | F2: Esvaziada dia 24/01/25 com 6ton aprox
A3: 2 | B3: =SUM('Acompanhamento Compostagem Alvo'!E25+'Acompanhamento Compostagem Alvo'!E26+'Acompanhamento Compostagem Alvo'!E27+'Acompanhamento Compostagem Alvo'!E28+'Acompanhamento Compostagem Alvo'!E29+'Acompanhamento Compostagem Alvo'!E30+'Acompanhamento Compostagem Alvo'!E31+'Acompanhamento Compostagem Alvo'!E32+'Acompanhamento Compostagem Alvo'!E33+'Acompanhamento Compostagem Alvo'!E34+'Acompanhamento Compostagem Alvo'!E35+'Acompanhamento Compostagem Alvo'!E36+'Acompanhamento Compostagem Alvo'!E37+'Acompanhamento Compostagem Alvo'!E38+'Acompanhamento Compostagem Alvo'!E39+'Acompanhamento Compostagem Alvo'!E40+'Acompanhamento Compostagem Alvo'!E41+'Acompanhamento Compostagem Alvo'!E42+'Acompanhamento Compostagem Alvo'!E43+'Acompanhamento Compostagem Alvo'!E44+'Acompanhamento Compostagem Alvo'!E50+'Acompanhamento Compostagem Alvo'!E51+'Acompanhamento Compostagem Alvo'!E52+'Acompanhamento Compostagem Alvo'!E53+'Acompanhamento Compostagem Alvo'!E54+'Acompanhamento Compostagem Alvo'!E55+'Acompanhamento Compostagem Alvo'!E64+'Acompanhamento Compostagem Alvo'!E65+'Acompanhamento Compostagem Alvo'!E66+'Acompanhamento Compostagem Alvo'!E67+'Acompanhamento Compostagem Alvo'!E68+'Acompanhamento Compostagem Alvo'!E75+'Acompanhamento Compostagem Alvo'!E76+'Acompanhamento Compostagem Alvo'!E77+'Acompanhamento Compostagem Alvo'!E78+'Acompanhamento Compostagem Alvo'!E79+'Acompanhamento Compostagem Alvo'!E83+'Acompanhamento Compostagem Alvo'!E84+'Acompanhamento Compostagem Alvo'!E85+'Acompanhamento Compostagem Alvo'!E86+'Acompanhamento Compostagem Alvo'!E87+'Acompanhamento Compostagem Alvo'!E88+'Acompanhamento Compostagem Alvo'!E89+'Acompanhamento Compostagem Alvo'!E90+B8) -> 22411.115 | C3: até 10/04/2024 = 5.605,02kg | D3: esvaziada dia 16/08/2024 com 4ton aprox. | E3: De 14/8 a 24/01/25 = 16.806,10 kg
A4: 3 | B4: =SUM('Acompanhamento Compostagem Alvo'!E45+'Acompanhamento Compostagem Alvo'!E46+'Acompanhamento Compostagem Alvo'!E47+'Acompanhamento Compostagem Alvo'!E48+'Acompanhamento Compostagem Alvo'!E49+'Acompanhamento Compostagem Alvo'!E56+'Acompanhamento Compostagem Alvo'!E57+'Acompanhamento Compostagem Alvo'!E58+'Acompanhamento Compostagem Alvo'!E59+'Acompanhamento Compostagem Alvo'!E60+'Acompanhamento Compostagem Alvo'!E61+'Acompanhamento Compostagem Alvo'!E62+'Acompanhamento Compostagem Alvo'!E63+'Acompanhamento Compostagem Alvo'!E69+'Acompanhamento Compostagem Alvo'!E70+'Acompanhamento Compostagem Alvo'!E71+'Acompanhamento Compostagem Alvo'!E72+'Acompanhamento Compostagem Alvo'!E73+'Acompanhamento Compostagem Alvo'!E74+'Acompanhamento Compostagem Alvo'!E80+'Acompanhamento Compostagem Alvo'!E81+'Acompanhamento Compostagem Alvo'!E82+'Acompanhamento Compostagem Alvo'!E91+'Acompanhamento Compostagem Alvo'!E92+'Acompanhamento Compostagem Alvo'!E93+'Acompanhamento Compostagem Alvo'!E94+'Acompanhamento Compostagem Alvo'!E95+'Acompanhamento Compostagem Alvo'!E96+'Acompanhamento Compostagem Alvo'!E97+'Acompanhamento Compostagem Alvo'!E98+'Acompanhamento Compostagem Alvo'!E106+'Acompanhamento Compostagem Alvo'!E107+'Acompanhamento Compostagem Alvo'!E108+'Acompanhamento Compostagem Alvo'!E109+'Acompanhamento Compostagem Alvo'!E110++'Acompanhamento Compostagem Alvo'!E111+'Acompanhamento Compostagem Alvo'!E117+'Acompanhamento Compostagem Alvo'!E118+'Acompanhamento Compostagem Alvo'!E122+'Acompanhamento Compostagem Alvo'!E123+'Acompanhamento Compostagem Alvo'!E124) -> 5057.21 | C4: até 02/05/2024 = 5.057,21 | D4: com 4 ton aprox.
A5: 4 | B5: ='Acompanhamento Compostagem Alvo'!E99+'Acompanhamento Compostagem Alvo'!E100+'Acompanhamento Compostagem Alvo'!E101+'Acompanhamento Compostagem Alvo'!E102+'Acompanhamento Compostagem Alvo'!E103+'Acompanhamento Compostagem Alvo'!E104+'Acompanhamento Compostagem Alvo'!E105+'Acompanhamento Compostagem Alvo'!E112+'Acompanhamento Compostagem Alvo'!E113+'Acompanhamento Compostagem Alvo'!E114+'Acompanhamento Compostagem Alvo'!E115+'Acompanhamento Compostagem Alvo'!E116+'Acompanhamento Compostagem Alvo'!E119+'Acompanhamento Compostagem Alvo'!E120+'Acompanhamento Compostagem Alvo'!E121+'Acompanhamento Compostagem Alvo'!E125+'Acompanhamento Compostagem Alvo'!E126+'Acompanhamento Compostagem Alvo'!E127+'Acompanhamento Compostagem Alvo'!E128+'Acompanhamento Compostagem Alvo'!E129+'Acompanhamento Compostagem Alvo'!E135+'Acompanhamento Compostagem Alvo'!E136+'Acompanhamento Compostagem Alvo'!E137+'Acompanhamento Compostagem Alvo'!E143+'Acompanhamento Compostagem Alvo'!E144+'Acompanhamento Compostagem Alvo'!E145+'Acompanhamento Compostagem Alvo'!E146+'Acompanhamento Compostagem Alvo'!E147+'Acompanhamento Compostagem Alvo'!E148+'Acompanhamento Compostagem Alvo'!E155+'Acompanhamento Compostagem Alvo'!E156+'Acompanhamento Compostagem Alvo'!E157+'Acompanhamento Compostagem Alvo'!E158+'Acompanhamento Compostagem Alvo'!E159+'Acompanhamento Compostagem Alvo'!E160+'Acompanhamento Compostagem Alvo'!E167+'Acompanhamento Compostagem Alvo'!E168+'Acompanhamento Compostagem Alvo'!E169+'Acompanhamento Compostagem Alvo'!E170+'Acompanhamento Compostagem Alvo'!E171+'Acompanhamento Compostagem Alvo'!E172+'Acompanhamento Compostagem Alvo'!E173+'Acompanhamento Compostagem Alvo'!E183+'Acompanhamento Compostagem Alvo'!E184+'Acompanhamento Compostagem Alvo'!E185+'Acompanhamento Compostagem Alvo'!E186+'Acompanhamento Compostagem Alvo'!E187+'Acompanhamento Compostagem Alvo'!E188+'Acompanhamento Compostagem Alvo'!E189+'Acompanhamento Compostagem Alvo'!E190+'Acompanhamento Compostagem Alvo'!E196+'Acompanhamento Compostagem Alvo'!E197+'Acompanhamento Compostagem Alvo'!E198+'Acompanhamento Compostagem Alvo'!E199+'Acompanhamento Compostagem Alvo'!E200+'Acompanhamento Compostagem Alvo'!E201+'Acompanhamento Compostagem Alvo'!E202+'Acompanhamento Compostagem Alvo'!E203+'Acompanhamento Compostagem Alvo'!E204+'Acompanhamento Compostagem Alvo'!E205+'Acompanhamento Compostagem Alvo'!E211+'Acompanhamento Compostagem Alvo'!E212+'Acompanhamento Compostagem Alvo'!E213+'Acompanhamento Compostagem Alvo'!E214+'Acompanhamento Compostagem Alvo'!E215+'Acompanhamento Compostagem Alvo'!E216+'Acompanhamento Compostagem Alvo'!E226+'Acompanhamento Compostagem Alvo'!E227+'Acompanhamento Compostagem Alvo'!E228+'Acompanhamento Compostagem Alvo'!E229+'Acompanhamento Compostagem Alvo'!E230+'Acompanhamento Compostagem Alvo'!E231+'Acompanhamento Compostagem Alvo'!E232+'Acompanhamento Compostagem Alvo'!E233+'Acompanhamento Compostagem Alvo'!E243+'Acompanhamento Compostagem Alvo'!E244+'Acompanhamento Compostagem Alvo'!E245+'Acompanhamento Compostagem Alvo'!E246+'Acompanhamento Compostagem Alvo'!E247+'Acompanhamento Compostagem Alvo'!E248+'Acompanhamento Compostagem Alvo'!E249+'Acompanhamento Compostagem Alvo'!E250+'Acompanhamento Compostagem Alvo'!E251+'Acompanhamento Compostagem Alvo'!E252+'Acompanhamento Compostagem Alvo'!E253+'Acompanhamento Compostagem Alvo'!E262+'Acompanhamento Compostagem Alvo'!E263+'Acompanhamento Compostagem Alvo'!E264+'Acompanhamento Compostagem Alvo'!E265+'Acompanhamento Compostagem Alvo'!E266+'Acompanhamento Compostagem Alvo'!E267+'Acompanhamento Compostagem Alvo'!E268+'Acompanhamento Compostagem Alvo'!E269+'Acompanhamento Compostagem Alvo'!E270+'Acompanhamento Compostagem Alvo'!E271+'Acompanhamento Compostagem Alvo'!E272+'Acompanhamento Compostagem Alvo'!E273+'Acompanhamento Compostagem Alvo'!E274+'Acompanhamento Compostagem Alvo'!E275+'Acompanhamento Compostagem Alvo'!E276+'Acompanhamento Compostagem Alvo'!E277+'Acompanhamento Compostagem Alvo'!E278+'Acompanhamento Compostagem Alvo'!E279+'Acompanhamento Compostagem Alvo'!E280+'Acompanhamento Compostagem Alvo'!E281+'Acompanhamento Compostagem Alvo'!E282+'Acompanhamento Compostagem Alvo'!E283+'Acompanhamento Compostagem Alvo'!E284 -> 11300.59 | C5: até 14/08/2024 = 11.300,59
A7: 1 | B7: =SUM('Acompanhamento Compostagem Alvo'!E130+'Acompanhamento Compostagem Alvo'!E131+'Acompanhamento Compostagem Alvo'!E132+'Acompanhamento Compostagem Alvo'!E133+'Acompanhamento Compostagem Alvo'!E134+'Acompanhamento Compostagem Alvo'!E138+'Acompanhamento Compostagem Alvo'!E139+'Acompanhamento Compostagem Alvo'!E140+'Acompanhamento Compostagem Alvo'!E141+'Acompanhamento Compostagem Alvo'!E142+'Acompanhamento Compostagem Alvo'!E149+'Acompanhamento Compostagem Alvo'!E150+'Acompanhamento Compostagem Alvo'!E151+'Acompanhamento Compostagem Alvo'!E152+'Acompanhamento Compostagem Alvo'!E153+'Acompanhamento Compostagem Alvo'!E154+'Acompanhamento Compostagem Alvo'!E161+'Acompanhamento Compostagem Alvo'!E162+'Acompanhamento Compostagem Alvo'!E163+'Acompanhamento Compostagem Alvo'!E164+'Acompanhamento Compostagem Alvo'!E165+'Acompanhamento Compostagem Alvo'!E166+'Acompanhamento Compostagem Alvo'!E174+'Acompanhamento Compostagem Alvo'!E175+'Acompanhamento Compostagem Alvo'!E176+'Acompanhamento Compostagem Alvo'!E177+'Acompanhamento Compostagem Alvo'!E178+'Acompanhamento Compostagem Alvo'!E179+'Acompanhamento Compostagem Alvo'!E180+'Acompanhamento Compostagem Alvo'!E181+'Acompanhamento Compostagem Alvo'!E182+'Acompanhamento Compostagem Alvo'!E206+'Acompanhamento Compostagem Alvo'!E207+'Acompanhamento Compostagem Alvo'!E208+'Acompanhamento Compostagem Alvo'!E209+'Acompanhamento Compostagem Alvo'!E210+'Acompanhamento Compostagem Alvo'!E217+'Acompanhamento Compostagem Alvo'!E218+'Acompanhamento Compostagem Alvo'!E219+'Acompanhamento Compostagem Alvo'!E220+'Acompanhamento Compostagem Alvo'!E221+'Acompanhamento Compostagem Alvo'!E222+'Acompanhamento Compostagem Alvo'!E223+'Acompanhamento Compostagem Alvo'!E224+'Acompanhamento Compostagem Alvo'!E225+'Acompanhamento Compostagem Alvo'!E234+'Acompanhamento Compostagem Alvo'!E235+'Acompanhamento Compostagem Alvo'!E236+'Acompanhamento Compostagem Alvo'!E237+'Acompanhamento Compostagem Alvo'!E238+'Acompanhamento Compostagem Alvo'!E239+'Acompanhamento Compostagem Alvo'!E240+'Acompanhamento Compostagem Alvo'!E241+'Acompanhamento Compostagem Alvo'!E242+'Acompanhamento Compostagem Alvo'!E254+'Acompanhamento Compostagem Alvo'!E255+'Acompanhamento Compostagem Alvo'!E256+'Acompanhamento Compostagem Alvo'!E257+'Acompanhamento Compostagem Alvo'!E258+'Acompanhamento Compostagem Alvo'!E259+'Acompanhamento Compostagem Alvo'!E260+'Acompanhamento Compostagem Alvo'!E261+'Acompanhamento Compostagem Alvo'!E191+'Acompanhamento Compostagem Alvo'!E192+'Acompanhamento Compostagem Alvo'!E193+'Acompanhamento Compostagem Alvo'!E194+'Acompanhamento Compostagem Alvo'!E195) -> 8143.42
A8: 2 | B8: =SUM('Acompanhamento Compostagem Alvo'!E285+'Acompanhamento Compostagem Alvo'!E286+'Acompanhamento Compostagem Alvo'!E287+'Acompanhamento Compostagem Alvo'!E288+'Acompanhamento Compostagem Alvo'!E289+'Acompanhamento Compostagem Alvo'!E290+'Acompanhamento Compostagem Alvo'!E291+'Acompanhamento Compostagem Alvo'!E292+'Acompanhamento Compostagem Alvo'!E293+'Acompanhamento Compostagem Alvo'!E294+'Acompanhamento Compostagem Alvo'!E295+'Acompanhamento Compostagem Alvo'!E296+'Acompanhamento Compostagem Alvo'!E297+'Acompanhamento Compostagem Alvo'!E298+'Acompanhamento Compostagem Alvo'!E299+'Acompanhamento Compostagem Alvo'!E300+'Acompanhamento Compostagem Alvo'!E301+'Acompanhamento Compostagem Alvo'!E302+'Acompanhamento Compostagem Alvo'!E303+'Acompanhamento Compostagem Alvo'!E304+'Acompanhamento Compostagem Alvo'!E305+'Acompanhamento Compostagem Alvo'!E306+'Acompanhamento Compostagem Alvo'!E307+'Acompanhamento Compostagem Alvo'!E308+'Acompanhamento Compostagem Alvo'!E309+'Acompanhamento Compostagem Alvo'!E310+'Acompanhamento Compostagem Alvo'!E311+'Acompanhamento Compostagem Alvo'!E312+'Acompanhamento Compostagem Alvo'!E313+'Acompanhamento Compostagem Alvo'!E314+'Acompanhamento Compostagem Alvo'!E315+'Acompanhamento Compostagem Alvo'!E316+'Acompanhamento Compostagem Alvo'!E317+'Acompanhamento Compostagem Alvo'!E318+'Acompanhamento Compostagem Alvo'!E319+'Acompanhamento Compostagem Alvo'!E320+'Acompanhamento Compostagem Alvo'!E321+'Acompanhamento Compostagem Alvo'!E322+'Acompanhamento Compostagem Alvo'!E323+'Acompanhamento Compostagem Alvo'!E324+'Acompanhamento Compostagem Alvo'!E325+'Acompanhamento Compostagem Alvo'!E326+'Acompanhamento Compostagem Alvo'!E327+'Acompanhamento Compostagem Alvo'!E328+'Acompanhamento Compostagem Alvo'!E329+'Acompanhamento Compostagem Alvo'!E330+'Acompanhamento Compostagem Alvo'!E331+'Acompanhamento Compostagem Alvo'!E332+'Acompanhamento Compostagem Alvo'!E333+'Acompanhamento Compostagem Alvo'!E334+'Acompanhamento Compostagem Alvo'!E335+'Acompanhamento Compostagem Alvo'!E336+'Acompanhamento Compostagem Alvo'!E337+'Acompanhamento Compostagem Alvo'!E338+'Acompanhamento Compostagem Alvo'!E339+'Acompanhamento Compostagem Alvo'!E340+'Acompanhamento Compostagem Alvo'!E341+'Acompanhamento Compostagem Alvo'!E342+'Acompanhamento Compostagem Alvo'!E343+'Acompanhamento Compostagem Alvo'!E344+'Acompanhamento Compostagem Alvo'!E345+'Acompanhamento Compostagem Alvo'!E346+'Acompanhamento Compostagem Alvo'!E347+'Acompanhamento Compostagem Alvo'!E348+'Acompanhamento Compostagem Alvo'!E349+'Acompanhamento Compostagem Alvo'!E350+'Acompanhamento Compostagem Alvo'!E351+'Acompanhamento Compostagem Alvo'!E352+'Acompanhamento Compostagem Alvo'!E353+'Acompanhamento Compostagem Alvo'!E354+'Acompanhamento Compostagem Alvo'!E355+'Acompanhamento Compostagem Alvo'!E356+'Acompanhamento Compostagem Alvo'!E357+'Acompanhamento Compostagem Alvo'!E358+'Acompanhamento Compostagem Alvo'!E359+'Acompanhamento Compostagem Alvo'!E360+'Acompanhamento Compostagem Alvo'!E361+'Acompanhamento Compostagem Alvo'!E362+'Acompanhamento Compostagem Alvo'!E363+'Acompanhamento Compostagem Alvo'!E364+'Acompanhamento Compostagem Alvo'!E365+'Acompanhamento Compostagem Alvo'!E366+'Acompanhamento Compostagem Alvo'!E367+'Acompanhamento Compostagem Alvo'!E368+'Acompanhamento Compostagem Alvo'!E377+'Acompanhamento Compostagem Alvo'!E378+'Acompanhamento Compostagem Alvo'!E379+'Acompanhamento Compostagem Alvo'!E386+'Acompanhamento Compostagem Alvo'!E387+'Acompanhamento Compostagem Alvo'!E388+'Acompanhamento Compostagem Alvo'!E392+'Acompanhamento Compostagem Alvo'!E393+'Acompanhamento Compostagem Alvo'!E394+'Acompanhamento Compostagem Alvo'!E404+'Acompanhamento Compostagem Alvo'!E405+'Acompanhamento Compostagem Alvo'!E409+'Acompanhamento Compostagem Alvo'!E410+'Acompanhamento Compostagem Alvo'!E412+'Acompanhamento Compostagem Alvo'!E416+'Acompanhamento Compostagem Alvo'!E417+'Acompanhamento Compostagem Alvo'!E421+'Acompanhamento Compostagem Alvo'!E422+'Acompanhamento Compostagem Alvo'!E423+'Acompanhamento Compostagem Alvo'!E424+'Acompanhamento Compostagem Alvo'!E429+'Acompanhamento Compostagem Alvo'!E430+'Acompanhamento Compostagem Alvo'!E431+'Acompanhamento Compostagem Alvo'!E438+'Acompanhamento Compostagem Alvo'!E439+'Acompanhamento Compostagem Alvo'!E440+'Acompanhamento Compostagem Alvo'!E445+'Acompanhamento Compostagem Alvo'!E446+'Acompanhamento Compostagem Alvo'!E451+'Acompanhamento Compostagem Alvo'!E452+'Acompanhamento Compostagem Alvo'!E457+'Acompanhamento Compostagem Alvo'!E458+'Acompanhamento Compostagem Alvo'!E466) -> 16806.095

Sheet Peso por mês
A1: Mês | B1: Peso (resíduos compostados em kg)
A2: 45588 | B2: ='Acompanhamento Compostagem Alvo'!E2+'Acompanhamento Compostagem Alvo'!E3+'Acompanhamento Compostagem Alvo'!E4+'Acompanhamento Compostagem Alvo'!E5+'Acompanhamento Compostagem Alvo'!E6 -> 312.235
A3: 45619 | B3: ='Acompanhamento Compostagem Alvo'!E7+'Acompanhamento Compostagem Alvo'!E8+'Acompanhamento Compostagem Alvo'!E9+'Acompanhamento Compostagem Alvo'!E10+'Acompanhamento Compostagem Alvo'!E12+'Acompanhamento Compostagem Alvo'!E13 -> 701.41
A4: 45649 | B4: ='Acompanhamento Compostagem Alvo'!E14+'Acompanhamento Compostagem Alvo'!E15+'Acompanhamento Compostagem Alvo'!E16+'Acompanhamento Compostagem Alvo'!E17+'Acompanhamento Compostagem Alvo'!E18+'Acompanhamento Compostagem Alvo'!E19+'Acompanhamento Compostagem Alvo'!E20+'Acompanhamento Compostagem Alvo'!E21 -> 1396.73
A5: 45315 | B5: ='Acompanhamento Compostagem Alvo'!E22+'Acompanhamento Compostagem Alvo'!E23+'Acompanhamento Compostagem Alvo'!E24+'Acompanhamento Compostagem Alvo'!E25+'Acompanhamento Compostagem Alvo'!E26+'Acompanhamento Compostagem Alvo'!E27+'Acompanhamento Compostagem Alvo'!E28+'Acompanhamento Compostagem Alvo'!E29+'Acompanhamento Compostagem Alvo'!E30 -> 1062.75
A6: 45346 | B6: ='Acompanhamento Compostagem Alvo'!E31+'Acompanhamento Compostagem Alvo'!E32+'Acompanhamento Compostagem Alvo'!E33+'Acompanhamento Compostagem Alvo'!E34+'Acompanhamento Compostagem Alvo'!E35+'Acompanhamento Compostagem Alvo'!E36+'Acompanhamento Compostagem Alvo'!E37+'Acompanhamento Compostagem Alvo'!E38+'Acompanhamento Compostagem Alvo'!E39+'Acompanhamento Compostagem Alvo'!E41+'Acompanhamento Compostagem Alvo'!E40+'Acompanhamento Compostagem Alvo'!E42+'Acompanhamento Compostagem Alvo'!E43+'Acompanhamento Compostagem Alvo'!E44 -> 1738.05
A7: 45375 | B7: ='Acompanhamento Compostagem Alvo'!E45+'Acompanhamento Compostagem Alvo'!E46+'Acompanhamento Compostagem Alvo'!E47+'Acompanhamento Compostagem Alvo'!E48+'Acompanhamento Compostagem Alvo'!E49+'Acompanhamento Compostagem Alvo'!E50+'Acompanhamento Compostagem Alvo'!E51+'Acompanhamento Compostagem Alvo'!E52+'Acompanhamento Compostagem Alvo'!E53+'Acompanhamento Compostagem Alvo'!E54+'Acompanhamento Compostagem Alvo'!E55+'Acompanhamento Compostagem Alvo'!E56+'Acompanhamento Compostagem Alvo'!E57+'Acompanhamento Compostagem Alvo'!E58+'Acompanhamento Compostagem Alvo'!E59+'Acompanhamento Compostagem Alvo'!E60+'Acompanhamento Compostagem Alvo'!E61+'Acompanhamento Compostagem Alvo'!E62+'Acompanhamento Compostagem Alvo'!E63+'Peso x tempo'!C45+'Peso x tempo'!C46+'Peso x tempo'!C47+'Peso x tempo'!C48+'Peso x tempo'!C49+'Peso x tempo'!C50 -> 3925.16
A8: 45406 | B8: ='Peso x tempo'!C51+'Peso x tempo'!C52+'Peso x tempo'!C53+'Peso x tempo'!C54+'Peso x tempo'!C55+'Acompanhamento Compostagem Alvo'!E99+'Acompanhamento Compostagem Alvo'!E100+'Acompanhamento Compostagem Alvo'!E101+'Acompanhamento Compostagem Alvo'!E102+'Acompanhamento Compostagem Alvo'!E103+'Acompanhamento Compostagem Alvo'!E104+'Acompanhamento Compostagem Alvo'!E105+'Peso x tempo'!C58+'Peso x tempo'!C59+'Peso x tempo'!C60+'Peso x tempo'!C61+'Peso x tempo'!C62+'Peso x tempo'!C63 -> 6411.24
A9: 45436 | B9: ='Peso x tempo'!C64+'Peso x tempo'!C65+'Peso x tempo'!C66+'Peso x tempo'!C67+'Peso x tempo'!C68+'Peso x tempo'!C69+'Peso x tempo'!C70+'Peso x tempo'!C71+'Peso x tempo'!C72+'Peso x tempo'!C73+'Peso x tempo'!C74+'Peso x tempo'!C75+'Peso x tempo'!C76+'Peso x tempo'!C77 -> 5915.78
A10: 45467 | B10: ='Peso x tempo'!C78+'Peso x tempo'!C79+'Peso x tempo'!C80+'Peso x tempo'!C81+'Peso x tempo'!C82+'Peso x tempo'!C83+'Peso x tempo'!C84+'Peso x tempo'!C85+'Peso x tempo'!C86+'Peso x tempo'!C87+'Peso x tempo'!C88+'Peso x tempo'!C89+'Peso x tempo'!C90+'Peso x tempo'!C91+'Peso x tempo'!C92 -> 4876.95
A11: 45497 | B11: ='Peso x tempo'!C93+'Peso x tempo'!C94+'Peso x tempo'!C95+'Peso x tempo'!C96+'Peso x tempo'!C97+'Peso x tempo'!C98+'Peso x tempo'!C99+'Peso x tempo'!C100+'Peso x tempo'!C101+'Peso x tempo'!C102+'Peso x tempo'!C103+'Peso x tempo'!C104+'Peso x tempo'!C105 -> 4347.52
A12: 45528 | B12: =sum('Peso x tempo'!C106:C118) -> 4560.04
A13: 45559 | B13: =sum('Peso x tempo'!C119:C127) -> 4363.19
A14: 45589 | B14: =SUM('Peso x tempo'!C128:C140) -> 4817.49
A15: 45620 | B15: =SUM('Peso x tempo'!C141:C149) -> 4075.03
A16: 45650 | B16: =SUM('Peso x tempo'!C150:C160) -> 4686.23
A17: 45316 | B17: =SUM('Peso x tempo'!C161:C173) -> 4178.16
A18: 45347 | B18: =SUM('Peso x tempo'!C174:C180) -> 2755.7
A19: 45376 | B19: =SUM('Peso x tempo'!C181:C184) -> 1865.19
A20: 45407 | B20: =SUM('Peso x tempo'!C185:C190) -> 1902.25
A21: 45437 | B21: =SUM('Peso x tempo'!C189:C196) -> 2648.02
A22: 45468 | B22: =SUM('Peso x tempo'!C197:C203) -> 2661.16
A23: 45498 | B23: =SUM('Peso x tempo'!C204:C210) -> 3003.88
A24: 45529 | B24: =SUM('Peso x tempo'!C211:C218) -> 3315.87
A25: 45560 | B25: =SUM('Peso x tempo'!C228:C232) -> 2950.72
A26: 45590 | B26: =SUM('Peso x tempo'!C228:C233) -> 3191.58
A27: 45621 | B27: =SUM('Peso x tempo'!C234:C238) -> 3140.41
A28: 45651 | B28: =SUM('Peso x tempo'!C239:C245) -> 3408.77
A29: 46048 | B29: =SUM('Peso x tempo'!C259:C276) -> 4115.17
A30: 46079 | B30: =SUM('Peso x tempo'!C260:C277) -> 4190.76
A31: 46107 | B31: =SUM('Peso x tempo'!C277:C297) -> 4440.1
A32: 46138 | B32: =SUM('Peso x tempo'!C298:C316) -> 4750.53
A33: 46168 | B33: =SUM('Peso x tempo'!C317:C329) -> 5024.92
A34: 46199 | B34: =SUM('Peso x tempo'!C329:C340) -> 5001.75
A35: 46229 | B35: =SUM('Peso x tempo'!C341:C356) -> 5544.54
A36: 46260
A37: 46291
A38: 46321
A39: 46352

Sheet Temperatura
A1: Data | B1: Temperatura (°C) | C1: Temperatura / leira
A2: 45218 | B2: 0 | C2: 1A
A3: 45221 | B3: 0 | C3: 1B
A4: 45226 | B4: 40 | C4: 1A
A5: 45228 | B5: 41 | C5: 1A
A6: 45233 | B6: 49 | C6: 1B
A7: 45236 | B7: 51 | C7: 1C
A8: 45240 | B8: 50 | C8: 1A
A9: 45247 | B9: 43 | C9: 1B
A10: 45251 | B10: 47 | C10: 1C
A11: 45258 | B11: 50 | C11: 1A
A12: 45265 | B12: 60 | C12: 1A
A13: 45265 | B13: 40 | C13: 1B
... A529: 45387 | B529: 64 | C529: 3B

Sheet Gráficos Temperaturas
J2: 1B | AU2: 2B
A3: 1A | J3: DATA | K3: TEMP. (°C) | T3: 1C | AC3: 1D | AL3: 2A | AU3: DATA | AV3: TEMP. (°C) | BD3: 2C | BM3: 2D
A4: DATA | B4: TEMP. (°C) | J4: 45233 | K4: 49 | T4: DATA | U4: TEMP. (°C) | AC4: DATA | AD4: TEMP. (°C) | AL4: DATA | AM4: TEMP. (°C) | AU4: 45309 | AV4: 52 | BD4: DATA | BE4: TEMP. (°C) | BM4: DATA | BN4: TEMP. (°C)
A5: 45226 | B5: 40 | J5: 45247 | K5: 43 | T5: 45236 | U5: 51 | AC5: 45265 | AD5: 56 | AL5: 45306 | AM5: 59 | AU5: 45310 | AV5: 48 | BD5: 45311 | BE5: 57
A6: 45228 | B6: 41 | J6: 45265 | K6: 40 | T6: 45251 | U6: 47 | AC6: 45266 | AD6: 51 | AL6: 45307 | AM6: 60 | AU6: 45311 | AV6: 51 | BD6: 45313 | BE6: 60
A7: 45240 | B7: 50 | J7: 45266 | K7: 53 | T7: 45265 | U7: 52 | AC7: 45268 | AD7: 50 | AL7: 45308 | AM7: 58 | AU7: 45313 | AV7: 44 | BD7: 45314 | BE7: 49
A8: 45258 | B8: 50 | J8: 45268 | K8: 53 | T8: 45266 | U8: 49 | AC8: 45272 | AD8: 42 | AL8: 45309 | AM8: 60 | AU8: 45314 | AV8: 58 | BD8: 45315 | BE8: 50
A9: 45265 | B9: 60 | J9: 45272 | K9: 56 | T9: 45268 | U9: 49 | AC9: 45273 | AD9: 56 | AL9: 45310 | AM9: 54 | AU9: 45315 | AV9: 48 | BD9: 45316 | BE9: 51
A10: 45266 | B10: 51 | J10: 45273 | K10: 52 | T10: 45272 | U10: 54 | AC10: 45274 | AD10: 56 | AL10: 45311 | AM10: 60 | AU10: 45316 | AV10: 54 | BD10: 45317 | BE10: 44
A11: 45268 | B11: 51 | J11: 45274 | K11: 51 | T11: 45273 | U11: 44 | AC11: 45275 | AD11: 56 | AL11: 45313 | AM11: 50 | AU11: 45317 | AV11: 54 | BD11: 45321 | BE11: 50
A12: 45272 | B12: 48 | J12: 45275 | K12: 55 | T12: 45274 | U12: 48 | AC12: 45276 | AD12: 53 | AL12: 45314 | AM12: 42 | AU12: 45321 | AV12: 53 | BD12: 45323 | BE12: 50
A13: 45273 | B13: 42 | J13: 45276 | K13: 52 | T13: 45275 | U13: 48 | AC13: 45277 | AD13: 56 | AL13: 45315 | AM13: 49 | AU13: 45323 | AV13: 54 | BD13: 45324 | BE13: 52
A14: 45274 | B14: 42 | J14: 45277 | K14: 54 | T14: 45276 | U14: 48 | AC14: 45278 | AD14: 55 | AL14: 45316 | AM14: 49 | AU14: 45327 | AV14: 59 | BD14: 45327 | BE14: 46
A15: 45275 | B15: 39 | J15: 45278 | K15: 54 | T15: 45277 | U15: 50 | AC15: 45279 | AD15: 62 | AL15: 45317 | AM15: 55 | AU15: 45328 | AV15: 55 | BD15: 45328 | BE15: 46
A16: 45276 | B16: 55 | J16: 45279 | K16: 54 | T16: 45278 | U16: 50 | AC16: 45280 | AD16: 60 | AL16: 45321 | AM16: 46 | AU16: 45329 | AV16: 57 | BD16: 45329 | BE16: 43
... A23: 45286 | B23: 56 | J23: 45289 | K23: 60 | T23: 45288 | U23: 64 | AC23: 45290 | AD23: 60 | AL23: 45330 | AM23: 60 | AU23: 45341 | AV23: 58 | BD23: 45341 | BE23: 38
A24: 45287 | B24: 52 | J24: 45290 | K24: 62 | T24: 45289 | U24: 61 | AC24: 45291 | AD24: 61 | AL24: 45331 | AM24: 60
A25: 45288 | B25: 56 | J25: 45291 | K25: 60 | T25: 45290 | U25: 63 | AC25: 45293 | AD25: 60 | AL25: 45334 | AM25: 60
A26: 45289 | B26: 50 | J26: 45293 | K26: 62 | T26: 45291 | U26: 62 | AC26: 45294 | AD26: 54 | AL26: 45336 | AM26: 61
A27: 45290 | B27: 50 | J27: 45294 | K27: 58 | T27: 45293 | U27: 58 | AC27: 45295 | AD27: 47 | AL27: 45337 | AM27: 59
A28: 45291 | B28: 64 | J28: 45295 | K28: 56 | T28: 45294 | U28: 52 | AC28: 45296 | AD28: 45 | AL28: 45338 | AM28: 57
A29: 45293 | B29: 61 | J29: 45296 | K29: 56 | T29: 45295 | U29: 47 | AC29: 45297 | AD29: 62 | AL29: 45341 | AM29: 57
A30: 45294 | B30: 50 | J30: 45297 | K30: 62 | T30: 45296 | U30: 54 | AC30: 45299 | AD30: 60
A31: 45295 | B31: 46 | J31: 45299 | K31: 64 | T31: 45297 | U31: 54 | AC31: 45300 | AD31: 60
A32: 45296 | B32: 47 | J32: 45300 | K32: 64 | T32: 45299 | U32: 62 | AC32: 45301 | AD32: 69
A33: 45297 | B33: 54 | J33: 45301 | K33: 60 | T33: 45300 | U33: 63 | AC33: 45302 | AD33: 68
A34: 45299 | B34: 47 | J34: 45302 | K34: 64 | T34: 45301 | U34: 64 | AC34: 45303 | AD34: 65
A35: 45300 | B35: 43 | J35: 45303 | K35: 63 | T35: 45302 | U35: 61 | AC35: 45306 | AD35: 64
A36: 45301 | B36: 53 | J36: 45306 | K36: 59 | T36: 45303 | U36: 64 | AC36: 45307 | AD36: 63
A37: 45302 | B37: 56 | J37: 45307 | K37: 60 | T37: 45306 | U37: 60 | AC37: 45308 | AD37: 60
A38: 45303 | B38: 63 | J38: 45308 | K38: 61 | T38: 45307 | U38: 58 | AC38: 45309 | AD38: 54
A39: 45306 | B39: 60 | J39: 45309 | K39: 60 | T39: 45308 | U39: 62 | AC39: 45310 | AD39: 60
A40: 45307 | B40: 57 | J40: 45310 | K40: 64 | T40: 45309 | U40: 57 | AC40: 45311 | AD40: 60
A41: 45308 | B41: 55 | J41: 45311 | K41: 62 | T41: 45310 | U41: 58 | AC41: 45313 | AD41: 60
... A73: 45359 | B73: 39 | J73: 45364 | K73: 39 | T73: 45362 | U73: 44 | AC73: 45366 | AD73: 41
A74: 45362 | B74: 39 | J74: 45366 | K74: 43 | T74: 45364 | U74: 44
A75: 45364 | B75: 38 | T75: 45366 | U75: 43
A76: 45366 | B76: 38

Sheet Tabela Acompanhamento Compostag
A1: Data | B1: Origem dos Resíduos/n° da bombonas | C1: Peso | D1: Obs. (qtde de bombonas, tipo de resíduos)

Sheet Tabela Acompanhamento Adubo
A1: Nome | B1: Data | C1: Local (destino) | D1: Composteira (origem) | E1: Destino do adubo | F1: Peso aproximado do adubo produzido (kg) | G1: Observações
A2: Equipe | B2: 45391 | C2: descanso | D2: leira 1 | F2: 2000
A3: Equipe | B3: 45392 | C3: descanso | D3: leira 2 | F3: 3000
A4: Equipe | B4: 45393 | C4: descanso | D4: leira 3 | F4: 2000
A5: Equipe | B5: 45399 | C5: descanso | D5: leira 4 | F5: 3000
A6: Equipe | B6: 45433 | C6: descanso | D6: Caixa 1 | F6: 355 | G6: bem seco e com pedaços de comida
A7: Equipe | B7: 45674 | C7: descanso | D7: leira 1 | F7: 3575 | G7: Com pedaços de embutidos
A8: Equipe | B8: 45730 | C8: descanso | D8: leira 2 | F8: 3780
A9: Equipe | B9: 45763 | C9: descanso | D9: Caixa 2 | F9: 450
A10: Equipe | B10: 45841 | C10: Parreral de uva | D10: Caixa 2 | F10: 410 | G10: bem seco e com pedaços de comida
A11: Equipe | B11: 45841 | C11: Parreral de uva | D11: Caixa 3 | F11: 320 | G11: bem seco e com pedaços de comida
A12: Equipe | B12: 45929 | C12: descanso | D12: Caixa 4 | F12: 450 | G12: Com cheiro forte mas sem pedaços de comida
A13: Equipe | B13: 45930 | C13: descanso | D13: Caixa 5 | F13: 400
A14: Equipe | B14: 45931 | C14: descanso | D14: Caixa 6 | F14: 416
A15: Equipe | B15: 45932 | C15: descanso | D15: Caixa 10 | F15: 420
A16: Equipe | B16: 45933 | C16: descanso | D16: Caixa 11
A17: Equipe | B17: 45943 | C17: descanso | D17: Caixa 12 | F17: 415 | G17: bem seco e com pedaços de comida
A18: Equipe | B18: 45952 | C18: descanso | D18: Caixa 13 | F18: 420 | G18: bem seco e com pedaços de comida
A19: Equipe | B19: 45966 | C19: descanso | D19: Caixa 14 | F19: 410 | G19: bem seco e com pedaços de comida
A20: Equipe | B20: 45980 | C20: descanso | D20: Caixa 15 | F20: 420 | G20: bem seco e com pedaços de comida
A21: Equipe | B21: 45986 | C21: descanso | D21: Caixa 16 | F21: 423 | G21: bem seco e com pedaços de comida
A22: Equipe | B22: 45995 | C22: descanso | D22: Caixa 9 | F22: 419 | G22: bem seco e com pedaços de comida
A23: Equipe | B23: 46001 | C23: descanso | D23: Caixa 8 | F23: 405 | G23: bem seco e com pedaços de comida
A24: Equipe | B24: 46007 | C24: descanso | D24: Caixa 5 | F24: 420 | G24: bem seco e com pedaços de comida
A25: Equipe | B25: 46013 | C25: descanso | D25: Caixa 6 | F25: 432 | G25: bem seco e com pedaços de comida
A26: Equipe | B26: 46034 | C26: descanso | D26: Leira 1 | F26: 500 | G26: bem seco e com pedaços de comida
A27: Equipe | B27: 46035 | C27: descanso | D27: Leira 1 | F27: 500 | G27: cheiro forte e ainda com pedaços
A28: Equipe | B28: 46041 | C28: descanso | D28: Leira 1 | F28: 500 | G28: cheiro forte e ainda com pedaços
... A38: Equipe | B38: 46072 | C38: descanso | D38: Caixa 1 | F38: 430 | G38: bem seco e com pedaços de comida
A39: Equipe | B39: 46077 | C39: descanso | D39: Caixa 3 | F39: 400
A40: Equipe | B40: 46077 | C40: descanso | D40: Caixa 2 | F40: 425
A41: Equipe | B41: 46079 | C41: descanso | D41: Caixa 4 | F41: 450
A42: Equipe | B42: 46091 | C42: descanso | D42: Caixa 8 | F42: 400
A43: Equipe | B43: 46092 | C43: descanso | D43: Caixa 17 | F43: 400
A44: Equipe | B44: 46093 | C44: descanso | D44: Caixa 16 | F44: 400
A45: Equipe | B45: 46093 | C45: descanso | D45: Caixa 15 | F45: 400
A46: Equipe | B46: 46099 | C46: descanso | D46: Caixa 18 | F46: 400
A47: Equipe | B47: 46120 | C47: descanso | D47: Caixa 5 | F47: 400
A48: Equipe | B48: 46121 | C48: descanso | D48: Caixa 6 | F48: 400
A49: Equipe | B49: 46136 | C49: descanso | D49: Caixa 13 | F49: 400 | G49: bem seco, com papel e algum residuos
...

Sheet Tabela Acompanhamento Leiras
A1: Data | B1: Leira ou Caixa | C1: Temperatura | D1: visão | E1: olfato | F1: tato

Sheet Tabela Acompanhamento Colheitas
A1: Data | B1: Espécie colheita | C1: Peso | D1: N° do Canteiro | E1: Observações

Sheet Tabela Acompanhamento Água e en
A1: Data | B1: Água Irrigação | D1: Água Leiras | F1: Tempo de uso do Jato | G1: Uso do trator (qual trator)?; se foi na mão, como foi? Quantas pessoas?
B2: Início | C2: Fim | D2: Início | E2: Fim

Sheet Análise sensorial
A1: data | B1: leira | C1: visão | D1: olfato | E1: tato
A2: 45314 | B2: 1 | C2: Locais com fungos aparentes (branco), com pontos variando entre seco e molhado. Baratas pequenas e outros animais andando por todas as seções | D2: Cheiro de terra, agua e citrico | E2: Quente em todas as seções, as primeiras estão mais asperas e as ultimas mais umidas
A3: 45314 | B3: 2 | C3: Seco | D3: Cheiro citrico | E3: Poda bem quente e com pouca umidade
A4: 45317 | B4: 1 | C4: Locais com fungos aparentes (branco), com pontos variando entre seco e molhado. Baratas pequenas e outros animais andando por todas as seções. Presença de passaros em cima da lona | D4: Cheiro de terra, agua e citrico | E4: Alguns locais com mais calor que outros, assim como a umidade. Vapor de água presente quando aperta o adubo mas ainda não esta todo homegeo
A5: 45317 | B5: 2 | C5: Seco, com buracos dos cachorros | D5: Cheiro Citrico e madeira | E5: Centro bem quente, não se tem uma homegenidade entre poda e residuos por ser o inicio
A6: 45321 | B6: 1 | C6: Locais com fungos aparentes (branco), molhado. Baratas pequenas e outros animais andando por todas as seções | D6: Cheiro de terra, agua e citrico | E6: Quente em todas as seções,sendo a primeira com menos calor e tamanho diminuindo de forma rapida
A7: 45321 | B7: 2 | C7: Seca, quente mas ainda sem a presença de microorganismo visiveis | D7: Cheiro citrico | E7: Poda bem quente e com pouca umidade

Sheet Peso total por seção
A1: Destino do resíduo / leira | B1: SUM de Peso (kg)
B2: 0
A3: 3 | B3: 602.54
A4: 1A | B4: 671.515
A5: 1B | B5: 892.73
A6: 1C | B6: 769.82
A7: 1D | B7: 471.71
A8: 2A | B8: 2547.3
A9: 2B | B9: 2381.68
A10: 2C | B10: 310.63
A11: 2D | B11: 365.41
A12: 3A | B12: 1204.48
A13: 3B | B13: 1403.46
A14: 4A | B14: 433.72
A15: Total geral | B15: 12054.995
